<?xml version="1.0" ?>
<!-- =================================================================================== -->
<!-- |    This document was autogenerated by xacro from robot.urdf.xacro               | -->
<!-- |    EDITING THIS FILE BY HAND IS NOT RECOMMENDED                                 | -->
<!-- =================================================================================== -->
<robot name="iiwa_14_r820_robot">
  <gazebo>
    <plugin filename="libgazebo_ros_control.so" name="gazebo_ros_control">
      <robotNamespace/>
      <robotSimType>gazebo_ros_control/DefaultRobotHWSim</robotSimType>
    </plugin>
  </gazebo>
  <gazebo reference="camera_link">
    <sensor name="camera" type="camera">
      <update_rate>30.0</update_rate>
      <camera name="tip_link_camera">
        <horizontal_fov>1.3962634</horizontal_fov>
        <image>
          <width>800</width>
          <height>800</height>
          <format>R8G8B8</format>
        </image>
        <clip>
          <near>0.02</near>
          <far>300</far>
        </clip>
        <noise>
          <type>gaussian</type>
          <!-- Noise is sampled independently per pixel on each frame.
                    That pixel's noise value is added to each of its color
                    channels, which at that point lie in the range [0,1]. -->
          <mean>0.0</mean>
          <stddev>0.007</stddev>
        </noise>
      </camera>
      <plugin filename="libgazebo_ros_camera.so" name="camera_controller">
        <alwaysOn>true</alwaysOn>
        <updateRate>0.0</updateRate>
        <cameraName>camera</cameraName>
        <imageTopicName>image_raw</imageTopicName>
        <cameraInfoTopicName>camera_info</cameraInfoTopicName>
        <frameName>camera_link</frameName>
        <hackBaseline>0.07</hackBaseline>
        <distortionK1>0.0</distortionK1>
        <distortionK2>0.0</distortionK2>
        <distortionK3>0.0</distortionK3>
        <distortionT1>0.0</distortionT1>
        <distortionT2>0.0</distortionT2>
      </plugin>
    </sensor>
  </gazebo>
  <link name="world"/>
  <link name="base_link">
    <visual>
      <origin rpy="0 0 0" xyz="0 0 0"/>
      <geometry>
        <mesh filename="model://tut-iiwa14/meshes/base.dae" scale="1 1 1"/>
      </geometry>
    </visual>
    <collision>
      <origin rpy="0 0 0" xyz="0 0 0"/>
      <geometry>
        <mesh filename="model://tut-iiwa14/meshes/base.dae" scale="1 1 1"/>
      </geometry>
    </collision>
    <inertial>
      <mass value="7.054081"/>
      <origin xyz="-0.012841 0.000000 0.071507"/>
      <inertia ixx="0.031237" ixy="0.0" ixz="0.000870" iyy="0.039718" iyz="0.0" izz="0.043120"/>
    </inertial>
  </link>
  <joint name="base_fixed_joint" type="fixed">
    <parent link="world"/>
    <child link="base_link"/>
    <origin rpy="0 0 0" xyz="0 0 0"/>
  </joint>
  <link name="link1">
    <visual>
      <origin rpy="0 0 0" xyz="0 0 0"/>
      <geometry>
        <mesh filename="model://tut-iiwa14/meshes/link1.dae" scale="1 1 1"/>
      </geometry>
    </visual>
    <collision>
      <origin rpy="0 0 0" xyz="0 0 0"/>
      <geometry>
        <mesh filename="model://tut-iiwa14/meshes/link1.dae" scale="1 1 1"/>
      </geometry>
    </collision>
    <inertial>
      <mass value="5.288551"/>
      <origin xyz="0.000001 -0.033788 0.122377"/>
      <inertia ixx="0.042430" ixy="0.0" ixz="0.000001" iyy="0.042810" iyz="0.006332" izz="0.015854"/>
    </inertial>
  </link>
  <joint name="a1" type="revolute">
    <parent link="base_link"/>
    <child link="link1"/>
    <origin rpy="0 0 0" xyz="0 0 0.1575"/>
    <axis xyz="0 0 1"/>
    <limit effort="1000" lower="-2.9670597283903604" upper="2.9670597283903604" velocity="1.4835298641951802"/>
  </joint>
  <transmission name="a1_tran">
    <type>transmission_interface/SimpleTransmission</type>
    <joint name="a1">
      <hardwareInterface>hardware_interface/PositionJointInterface</hardwareInterface>
      <mechanicalReduction>1</mechanicalReduction>
    </joint>
    <actuator name="a1_motor">
      <hardwareInterface>hardware_interface/PositionJointInterface</hardwareInterface>
      <mechanicalReduction>1</mechanicalReduction>
    </actuator>
  </transmission>
  <link name="link2">
    <visual>
      <origin rpy="0 0 0" xyz="0 0 0"/>
      <geometry>
        <mesh filename="model://tut-iiwa14/meshes/link2.dae" scale="1 1 1"/>
      </geometry>
    </visual>
    <collision>
      <origin rpy="0 0 0" xyz="0 0 0"/>
      <geometry>
        <mesh filename="model://tut-iiwa14/meshes/link2.dae" scale="1 1 1"/>
      </geometry>
    </collision>
    <inertial>
      <mass value="5.688776"/>
      <origin xyz="0.000137 0.037540 0.076351"/>
      <inertia ixx="0.055162" ixy="-0.000032" ixz="0.000056" iyy="0.053966" iyz="0.010025" izz="0.016512"/>
    </inertial>
  </link>
  <joint name="a2" type="revolute">
    <parent link="link1"/>
    <child link="link2"/>
    <origin rpy="0 0 0" xyz="0 0 0.2025"/>
    <axis xyz="0 1 0"/>
    <limit effort="1000" lower="-2.0943951023931953" upper="2.0943951023931953" velocity="1.4835298641951802"/>
  </joint>
  <transmission name="a2_tran">
    <type>transmission_interface/SimpleTransmission</type>
    <joint name="a2">
      <hardwareInterface>hardware_interface/PositionJointInterface</hardwareInterface>
      <mechanicalReduction>1</mechanicalReduction>
    </joint>
    <actuator name="a2_motor">
      <hardwareInterface>hardware_interface/PositionJointInterface</hardwareInterface>
      <mechanicalReduction>1</mechanicalReduction>
    </actuator>
  </transmission>
  <link name="link3">
    <visual>
      <origin rpy="0 0 0" xyz="0 0 0"/>
      <geometry>
        <mesh filename="model://tut-iiwa14/meshes/link3.dae" scale="1 1 1"/>
      </geometry>
    </visual>
    <collision>
      <origin rpy="0 0 0" xyz="0 0 0"/>
      <geometry>
        <mesh filename="model://tut-iiwa14/meshes/link3.dae" scale="1 1 1"/>
      </geometry>
    </collision>
    <inertial>
      <mass value="3.460524"/>
      <origin xyz="0.000000 0.034907 0.113092"/>
      <inertia ixx="0.021705" ixy="0.0" ixz="0.0" iyy="0.020716" iyz="-0.003840" izz="0.007692"/>
    </inertial>
  </link>
  <joint name="a3" type="revolute">
    <parent link="link2"/>
    <child link="link3"/>
    <origin rpy="0 0 0" xyz="0 0 0.2373"/>
    <axis xyz="0 0 1"/>
    <limit effort="1000" lower="-2.9670597283903604" upper="2.9670597283903604" velocity="1.7453292519943295"/>
  </joint>
  <transmission name="a3_tran">
    <type>transmission_interface/SimpleTransmission</type>
    <joint name="a3">
      <hardwareInterface>hardware_interface/PositionJointInterface</hardwareInterface>
      <mechanicalReduction>1</mechanicalReduction>
    </joint>
    <actuator name="a3_motor">
      <hardwareInterface>hardware_interface/PositionJointInterface</hardwareInterface>
      <mechanicalReduction>1</mechanicalReduction>
    </actuator>
  </transmission>
  <link name="link4">
    <visual>
      <origin rpy="0 0 0" xyz="0 0 0"/>
      <geometry>
        <mesh filename="model://tut-iiwa14/meshes/link4.dae" scale="1 1 1"/>
      </geometry>
    </visual>
    <collision>
      <origin rpy="0 0 0" xyz="0 0 0"/>
      <geometry>
        <mesh filename="model://tut-iiwa14/meshes/link4.dae" scale="1 1 1"/>
      </geometry>
    </collision>
    <inertial>
      <mass value="4.122630"/>
      <origin xyz="0.000000 -0.029288 0.086968"/>
      <inertia ixx="0.032396" ixy="0.0" ixz="0.0" iyy="0.030747" iyz="-0.006017" izz="0.009876"/>
    </inertial>
  </link>
  <joint name="a4" type="revolute">
    <parent link="link3"/>
    <child link="link4"/>
    <origin rpy="0 0 0" xyz="0 0 0.182"/>
    <axis xyz="0 1 0"/>
    <limit effort="1000" lower="-2.0943951023931953" upper="2.0943951023931953" velocity="1.3089969389957472"/>
  </joint>
  <transmission name="a4_tran">
    <type>transmission_interface/SimpleTransmission</type>
    <joint name="a4">
      <hardwareInterface>hardware_interface/PositionJointInterface</hardwareInterface>
      <mechanicalReduction>1</mechanicalReduction>
    </joint>
    <actuator name="a4_motor">
      <hardwareInterface>hardware_interface/PositionJointInterface</hardwareInterface>
      <mechanicalReduction>1</mechanicalReduction>
    </actuator>
  </transmission>
  <link name="link5">
    <visual>
      <origin rpy="0 0 0" xyz="0 0 0"/>
      <geometry>
        <mesh filename="model://tut-iiwa14/meshes/link5.dae" scale="1 1 1"/>
      </geometry>
    </visual>
    <collision>
      <origin rpy="0 0 0" xyz="0 0 0"/>
      <geometry>
        <mesh filename="model://tut-iiwa14/meshes/link5.dae" scale="1 1 1"/>
      </geometry>
    </collision>
    <inertial>
      <mass value="1.563267"/>
      <origin xyz="0.000000 -0.029828 0.066251"/>
      <inertia ixx="0.008668" ixy="0.0" ixz="0.0" iyy="0.007290" iyz="0.002866" izz="0.003930"/>
    </inertial>
  </link>
  <joint name="a5" type="revolute">
    <parent link="link4"/>
    <child link="link5"/>
    <origin rpy="0 0 0" xyz="0 0 0.2168"/>
    <axis xyz="0 0 1"/>
    <limit effort="1000" lower="-2.9670597283903604" upper="2.9670597283903604" velocity="2.2689280275926285"/>
  </joint>
  <transmission name="a5_tran">
    <type>transmission_interface/SimpleTransmission</type>
    <joint name="a5">
      <hardwareInterface>hardware_interface/PositionJointInterface</hardwareInterface>
      <mechanicalReduction>1</mechanicalReduction>
    </joint>
    <actuator name="a5_motor">
      <hardwareInterface>hardware_interface/PositionJointInterface</hardwareInterface>
      <mechanicalReduction>1</mechanicalReduction>
    </actuator>
  </transmission>
  <link name="link6">
    <visual>
      <origin rpy="0 0 0" xyz="0 0 0"/>
      <geometry>
        <mesh filename="model://tut-iiwa14/meshes/link6.dae" scale="1 1 1"/>
      </geometry>
    </visual>
    <collision>
      <origin rpy="0 0 0" xyz="0 0 0"/>
      <geometry>
        <mesh filename="model://tut-iiwa14/meshes/link6.dae" scale="1 1 1"/>
      </geometry>
    </collision>
    <inertial>
      <mass value="2.328466"/>
      <origin xyz="0.000001 0.000327 0.000604"/>
      <inertia ixx="0.006302" ixy="0.0" ixz="0.0" iyy="0.006032" iyz="0.000314" izz="0.004589"/>
    </inertial>
  </link>
  <joint name="a6" type="revolute">
    <parent link="link5"/>
    <child link="link6"/>
    <origin rpy="0 0 0" xyz="0 0 0.1825"/>
    <axis xyz="0 1 0"/>
    <limit effort="1000" lower="-2.0943951023931953" upper="2.0943951023931953" velocity="2.356194490192345"/>
  </joint>
  <transmission name="a6_tran">
    <type>transmission_interface/SimpleTransmission</type>
    <joint name="a6">
      <hardwareInterface>hardware_interface/PositionJointInterface</hardwareInterface>
      <mechanicalReduction>1</mechanicalReduction>
    </joint>
    <actuator name="a6_motor">
      <hardwareInterface>hardware_interface/PositionJointInterface</hardwareInterface>
      <mechanicalReduction>1</mechanicalReduction>
    </actuator>
  </transmission>
  <link name="link7">
    <visual>
      <origin rpy="0 0 0" xyz="0 0 0"/>
      <geometry>
        <mesh filename="model://tut-iiwa14/meshes/link7.dae" scale="1 1 1"/>
      </geometry>
    </visual>
    <collision>
      <origin rpy="0 0 0" xyz="0 0 0"/>
      <geometry>
        <mesh filename="model://tut-iiwa14/meshes/link7.dae" scale="1 1 1"/>
      </geometry>
    </collision>
    <inertial>
      <mass value="0.393705"/>
      <origin xyz="0.000002 -0.000001 0.016970"/>
      <inertia ixx="0.000285" ixy="0.0" ixz="0.0" iyy="0.000285" iyz="0.0" izz="0.000445"/>
    </inertial>
  </link>
  <joint name="a7" type="revolute">
    <parent link="link6"/>
    <child link="link7"/>
    <origin rpy="0 0 0" xyz="0 0 0.081"/>
    <axis xyz="0 0 1"/>
    <limit effort="1000" lower="-3.0543261909900763" upper="3.0543261909900763" velocity="2.356194490192345"/>
  </joint>
  <transmission name="a7_tran">
    <type>transmission_interface/SimpleTransmission</type>
    <joint name="a7">
      <hardwareInterface>hardware_interface/PositionJointInterface</hardwareInterface>
      <mechanicalReduction>1</mechanicalReduction>
    </joint>
    <actuator name="a7_motor">
      <hardwareInterface>hardware_interface/PositionJointInterface</hardwareInterface>
      <mechanicalReduction>1</mechanicalReduction>
    </actuator>
  </transmission>

  <joint name="iiwa7_joint_ee" type="fixed">
    <parent link="link7"/>
    <child link="iiwa7_link_ee"/>
    <origin xyz="0 0 0.126" rpy="0 0 0"/>
  </joint>

  <!-- SCHUNK EGP 40 EEF -->
  <!-- Base -->
  <link name="iiwa7_link_ee">
    <inertial>
      <mass value="0.6" />
      <origin rpy="0 0 0" xyz="0.00078059 -0.00070996 0.04726637" />
      <inertia ixx="0.0011357" ixy="-0.00000024461" ixz="0.000014912" iyy="0.0012832" iyz="0.0000085651" izz="0.00066545" />
    </inertial>
    <visual>
      <origin rpy="0 0 0" xyz="0 0 0" />
      <geometry>
        <mesh filename="model://schunk-egp-40/meshes/visual/obj/schunk_low_baked_small.obj" scale="1 1 1" />
      </geometry>
      <material name="white">
        <color rgba="1 1 1 1"/>
      </material>
    </visual>
    <collision>
      <origin rpy="0 0 0" xyz="0 0 0" />
      <geometry>
        <mesh filename="model://schunk-egp-40/meshes/visual/dae/schunk-egp-40-collision.dae" scale="1 1 1" />
      </geometry>
    </collision>
  </link>

  <!-- Finger 1 -->
  <link name="SchunkEGP40_Finger1_link">
    <inertial>
      <mass value="0.04" />
      <origin rpy="0 0 0" xyz="0 0 0" />
      <inertia ixx="0.0000013454" ixy="0" ixz="0" iyy="0.00000061207" iyz="0" izz="0.00000097333" />
    </inertial>
    <visual>
      <origin rpy="0 0 0" xyz="0 0 0" />
      <geometry>
        <mesh filename="model://schunk-egp-40/meshes/visual/dae/schunk-egp-40-finger-base.dae" scale="1 1 1" />
      </geometry>
      <material name="black">
        <color rgba="0 0 0 1"/>
      </material>
    </visual>
    <visual>
      <origin rpy="0 0 0" xyz="0 0 0" />
      <geometry>
        <mesh filename="model://schunk-egp-40/meshes/visual/obj/schunk_coact_finger_1.obj" scale="1 1 1" />
      </geometry>
      <material name="schunk_coact_finger_1_blue">
        <color rgba="0 0 0.8 1"/>
      </material>
    </visual>
    <collision>
      <origin rpy="0 0 0" xyz="0 0.0005 0.006075" />
      <geometry>
        <box size="0.006 0.016 0.01215" />
      </geometry>
    </collision>
    <collision>
      <origin rpy="0 0 0" xyz="0 0.0005 0.006075" />
      <geometry>
        <mesh filename="model://schunk-egp-40/meshes/visual/obj/schunk_coact_finger_1.obj" scale="1 1 1" />
      </geometry>
    </collision>
  </link>

  <!-- Finger 2 -->
  <link name="SchunkEGP40_Finger2_link">
    <inertial>
      <mass value="0.04" />
      <origin rpy="0 0 0" xyz="0 0 0" />
      <inertia ixx="0.0000013454" ixy="0" ixz="0" iyy="0.00000061207" iyz="0" izz="0.00000097333" />
    </inertial>
    <visual>
      <origin rpy="0 0 0" xyz="0 0 0" />
      <geometry>
        <mesh filename="model://schunk-egp-40/meshes/visual/dae/schunk-egp-40-finger-base.dae" scale="1 1 1" />
      </geometry>
      <material name="black">
        <color rgba="0 0 0 1"/>
      </material>
    </visual>
    <visual>
      <origin rpy="0 0 0" xyz="0 0 0" />
      <geometry>
        <mesh filename="model://schunk-egp-40/meshes/visual/obj/schunk_coact_finger_1.obj" scale="1 1 1" />
      </geometry>
      <material name="schunk_coact_finger_1_blue">
        <color rgba="0 0 0.8 1"/>
      </material>
    </visual>
    <collision>
      <origin rpy="0 0 0" xyz="0 0.0005 0.006075" />
      <geometry>
        <box size="0.006 0.016 0.01215" />
      </geometry>
    </collision>
    <collision>
      <origin rpy="0 0 0" xyz="0 0.0005 0.006075" />
      <geometry>
        <mesh filename="model://schunk-egp-40/meshes/visual/obj/schunk_coact_finger_1.obj" scale="1 1 1" />
      </geometry>
    </collision>
  </link>

  <!-- Finger Joint 1 -->
  <joint name="SchunkEGP40_Finger1_joint" type="prismatic">
    <origin xyz="0.006800 0.000500 0.108000" rpy="0 0 0" />
    <axis xyz="1 0 0" />
    <limit effort="1" lower="0" upper="0.01" velocity="-1" />
    <dynamics damping="1.0" />
    <parent link="iiwa7_link_ee" />
    <child link="SchunkEGP40_Finger1_link" />
  </joint>
  <gazebo reference="SchunkEGP40_Finger1_joint">
    <provideFeedback>1</provideFeedback>
    <implicitSpringDamper>1</implicitSpringDamper>
  </gazebo>

  <!-- Finger Joint 2 -->
  <joint name="SchunkEGP40_Finger2_joint" type="prismatic">
    <origin xyz="-0.006800 0.000500 0.108000" rpy="0 0 3.14" />
    <axis xyz="1 0 0" />
    <limit effort="1" lower="0" upper="0.01" velocity="-1" />
    <dynamics damping="1.0" />
    <parent link="iiwa7_link_ee" />
    <child link="SchunkEGP40_Finger2_link" />
  </joint>
  <gazebo reference="SchunkEGP40_Finger2_joint">
    <provideFeedback>1</provideFeedback>
    <implicitSpringDamper>1</implicitSpringDamper>
  </gazebo>
</robot>

